Workbook
Name Grains: #REF!
Name Grains: #REF!
Name inc: '[1]Income tax'!$L$5
Name inc: #REF!
Name Rates2: '[2]5. Income tax'!$F$27:$H$33
Name Rates2: '[1]Income tax'!$F$6:$H$12
Name Rates2: #REF!

Sheet Guidance
C2: Living Wage Benchmark
C4: Descriptions of the tabs in the tool
C6: Tab | E6: Description
C7: OUTPUT_Living Wage | E7: Overall results of the Living Income Benchmarks.
C8: 1. Setting the boundaries | E8: Define the Reference Household size and geographical focus for the calculation of the LW Benchmark
C9: 2. Housing costs | E9: Overview of Housing cost results
C10: CLS - Input data | E10: Input sheet for the Cost of Living Survey (CLS)
C11: Decent Housing | E11: Input sheet for the evaluation of local decent housing criteria
C12: 3. Food costs | E12: Overview of Food Costs results based on a model diet and a referenced sized household
C13: Food costs - Input data | E13: Input sheet for food prices from the the Food Price Survey
C14: Nutritional input | E14: Define and adjust the required calorie intake and nutritional values of food
C15: 4. NFNH costs | E15: Non-Food Non Housing cost estimation based on the expenditure weights of a consumer price index (CPI)
C16: Income tax | E16: Calculation of the income tax. Adapt and adjust tax brackets and tax rates.
C17: Background calculations | E17: This tab presents the detailed logics and calculations applied throughout the model.
... C28: Model Maintenance | E28: Guidance
E29: All cells (excluding inputs) and calculations are blocked. Users are not allowed to add any rows or columns (except for the food cost tab, if necessary). We strongly recommend to keep the excel file protected to avoid structural changes to the model.
E30: If needed, it is possible to remove the cell protection by clicking on "unprotect sheet" in the Review function in the tool bar above. The password is provided below.

Sheet OUTPUT_Living wage
C2: Living Wage Benchmark
I4: Source | J4: Instructions
C5: Country | E5: UGANDA | J5: Write the country of study
C6: Region | E6: Central Uganda | J6: Write the region of study
C7: Zone | E7: Peri-urban | J7: Do not directly edit cell E7. You can change the zone in "1. Setting the boundaries" tab
C10: Exchange rate | D10: LCU to USD | E10: 3675 | I10: LINK | J10: Gather the most recent exchange rate from the source provided
C13: Reference Household size | J13: Instructions
E15: Personalized | J15: Use the drop down menu in cell E15 to select betwee nthe calculated reference household size or the personalized household sice
C18: Number of adults | E18: =IF($E$15='Background calculations'!$B$11,'1. Setting the boundaries'!D25 + '1. Setting the boundaries'!D26,'1. Setting the boundaries'!D16) -> 2 | J18: The personalized household size can be edited in the 1. Setting the boundaries tab in cells D25 - D28
C19: Number of children | E19: =IF($E$15='Background calculations'!$B$11,'1. Setting the boundaries'!D27,'1. Setting the boundaries'!D17) -> 2
C20: Number of working adults | E20: =IF($E$15='Background calculations'!$B$11,'1. Setting the boundaries'!D28,'1. Setting the boundaries'!D18) -> 2
F22: =SUM(E27:E29)*5% -> 64973.294
C24: Living Income benchmark - Monthly results
E26: LCU/month | G26: USD/month | I26: ?
C27: Housing | E27: ='2. Housing costs'!D13 -> 98297.021 | G27: =IFERROR(E27/$E$10,"") -> 26.747489
C28: Food | E28: ='3. Food costs'!E14 -> 648047.94 | G28: =IFERROR(E28/$E$10,"") -> 176.33958
C29: NFNH | E29: ='4. NFNH costs'!E16 -> 553120.92 | G29: =IFERROR(E29/$E$10,"") -> 150.50909
C30: Cost of elder care | E30: =SUM(E27:E29)*5% -> 64973.294 | G30: =IFERROR(E30/$E$10,"") -> 17.679808
C31: Margins (unexpected events) | E31: =SUM(E28:E30)*5% -> 63307.107 | G31: =IFERROR(F22/$E$10,"") -> 17.679808
C33: Cost of basic but decent life for a typical household | E33: =SUM(E27:E31) -> 1427746.3 | G33: =SUM(G27:G31) -> 388.95577
C35: Net living wage (1 FTE sustaining the Reference Household) | E35: =IFERROR(E33/E20,"") -> 713873.14 | G35: =IFERROR(G33/E20,"") -> 194.47789
C37: Income tax | E37: =+'5. Income tax'!D23 -> 147689.9 | G37: =IFERROR(E37/E10,"") -> 40.187727
C39: Gross living wage (1 FTE sustaining the Reference Household) | E39: =+'5. Income tax'!$D$19/12 -> 1507940.7 | G39: =IFERROR(G35+G37,"") -> 234.66561
C42: Living Income benchmark - Yearly results
E44: LCU/year | G44: USD/year
C45: Housing | E45: =IFERROR(E27*12,"") -> 1179564.2 | G45: =IFERROR(G27*12,"") -> 320.96986
C46: Food | E46: =IFERROR(E28*12,"") -> 7776575.3 | G46: =IFERROR(G28*12,"") -> 2116.0749
C47: NFNH | E47: =IFERROR(E29*12,"") -> 6637451 | G47: =IFERROR(G29*12,"") -> 1806.1091
C48: Margins (unexpected events) | E48: =IFERROR(E30*12,"") -> 779679.53 | G48: =IFERROR(G30*12,"") -> 212.15769
C50: Cost of basic but decent life for a typical household | E50: =SUM(E45:E48) -> 16373270 | G50: =SUM(G45:G48) -> 4455.3116
C52: Income tax | E52: =IFERROR(E37*12,"") -> 1772278.7 | G52: =IFERROR(G37*12,"") -> 482.25272
C54: Gross living wage (1 FTE sustaining the Reference Household) | E54: =IFERROR(E50+E52,"") -> 18145549 | G54: =IFERROR(G50+G52,"") -> 4937.5643

Sheet 1. Setting the boundaries
B2: Setting the boundaries of the study
B5: 1) DEFINE GEOGRAPHICAL FOCUS
I7: Instructions
C8: Zone: | D8: Peri-urban | I8: Select one zone for the study from the drop-down menu (urban, peri-urban, rural)
C9: Zone (code): | D9: =IF(D8="Urban", "Urban", IF(D8="Peri-urban", "Region", "Rural")) -> Region | I9: Do not edit cell D9
B11: 2) ESTIMATE REFERENCE HOUSEHOLD SIZE
C13: Reference Household size | I13: Instructions
I14: Do not edit cells D16-D18. The number of adults for the Reference Household Size is assumed fixed (2 adults). If you want to calculate the Living Income Benchmark for another Reference Household Size enter a personalized household composition, the model will automatecally apply the calculations in the background and the results will be available in the OUTPUT dashboard when selecting the personalized houshold size option
D15: Model
C16: Number of adults | D16: 2
C17: Number of children | D17: =IFERROR(_xlfn.XLOOKUP($D$9,$D$43:$F$43,$D$48:$F$48),"") -> 0.0814875
C18: Number of working adults | D18: =_xlfn.IFNA(_xlfn.XLOOKUP($D$8,$D$63:$F$63,$D$68:$F$68),"") -> 1.733902
C22: Personalize household composition
I23: For an alternative calculation enter a personalized household composition in cells D25 - D28 Select the Household Composition to use in the OUTPUT dashboard and the model will autmoatically adjust all calculations.
D24: Personalized
C25: Number of adults (male) | D25: 1
C26: Number of adults (female) | D26: 1
C27: Number of children | D27: 2
C28: Number of working adults | D28: 2
B31: 2A) Calculate number of children
C33: Instructions
C34: The data for this section (2A) will need to be gathered from: | E34: LINK
C36: Guidance
B37: 1 | C37: If you are carrying out a study for a URBAN AREA, then collect data from both the Urban indicator & the region-specific indicator. Hence, you will need to collect two data points for each variable
B38: 2 | C38: If you are carrying out a study for a PERI-URBAN AREA, then collect data only from the region-specific indicator. Hence, you will need to collect one data points for each variable
B39: 3 | C39: If you are carrying out a study for a RURAL AREA, then collect data from both the Rural indicator & the region-specific indicator. Hence, you will need to collect two data points for each variable
B40: 4 | C40: Select the country of your study
B41: 5 | C41: Select always the latest available data
J42: Data for 2019
D43: Urban | E43: Rural | F43: Region | I43: Instructions
C44: Household size | D44: 0.12916667 | E44: 0.12916667 | F44: 0.12916667 | I44: Go to the link provided in cell E34. Retrieve this data by choosing --> Category: Population; Indicator: Average Household size | J44: Region data - for South
C45: Fertility rate | D45: 0.17013889 | E45: 0.17013889 | F45: 0.17083333 | I45: Go to the link provided in cell E34. Retrieve this data by choosing --> Category: Fertility; Indicator: Total Fertility Rate | J45: From census - national data
C46: Child mortality under five | D46: 46 | E46: 46 | F46: 46 | I46: Go to the link provided in cell E34. Retrieve this data by choosing --> Category: Child mortality; Indicator: Under five mortality rate
C48: Number of children | D48: =IFERROR(AVERAGE('Background calculations'!C24:C25,'Background calculations'!E24:E25),"") -> -0.38638646 | E48: =IFERROR(AVERAGE('Background calculations'!D24:D25,'Background calculations'!E24:E25),"") -> -0.38638646 | F48: =AVERAGE('Background calculations'!E24:E25) -> 0.0814875
B50: 2B) Calculate number of workers in the family
C52: Instructions
C53: The data for this section (2B) will need to be gathered from: | E53: LINK
C55: Guidance
B56: 1 | C56: If you are carrying out a study for a URBAN AREA, then collect data from the Urban indicator. Hence, you will need to collect only one data point for each variable
B57: 2 | C57: If you are carrying out a study for a PERI-URBAN AREA, then collect data only from both Urban and Rural indicators. Hence, you will need to collect two data points (both Urban and Rural) for each variable
...

Sheet 2. Housing costs
B2: Estimating housing costs
B4: 1) HOUSING COSTS FOR REFERENCE HOUSEHOLD SIZE
B6: Guidance
B7: Do not edit any cells and tables shown below, or add any new rows nor columns
C9: HOUSING COSTS
C11: Housing cost for Reference Household Size
D12: LCU / household / month | F12: USD / household / month
C13: Estimated monthly cost (incl. utilities) | D13: =IFERROR(G50*D28,"") -> 98297.021 | F13: =IFERROR(D13/'OUTPUT_Living wage'!$E$10,"") -> 26.747489
C16: Housing cost components
C18: Rent | D18: =IFERROR(D13*'Background calculations'!C89,"") -> 36889.604 | F18: =IFERROR(D18/'OUTPUT_Living wage'!$E$10,"") -> 10.037987
C19: Electricity | D19: =IFERROR(D13*'Background calculations'!C90,"") -> 11014.149 | F19: =IFERROR(D19/'OUTPUT_Living wage'!$E$10,"") -> 2.9970474
C20: Water | D20: =IFERROR(D13*'Background calculations'!C91,"") -> 5129.9504 | F20: =IFERROR(D20/'OUTPUT_Living wage'!$E$10,"") -> 1.3959049
C21: Cooking Fuel | D21: =IFERROR(D13*'Background calculations'!C92,"") -> 45263.317 | F21: =IFERROR(D21/'OUTPUT_Living wage'!$E$10,"") -> 12.316549
C24: Household Composition
C25: Selected | D25: ='OUTPUT_Living wage'!$E$15 -> Personalized
C26: Household Size | D26: =IFERROR('Background calculations'!D10+'Background calculations'!D11,0) -> 4
C27: Maximum number of people per room | D27: 2
C28: Total Rooms for Reference Household Size | D28: =ROUNDUP(D26/D27,0) -> 2
C31: Housing Survey Results
C33: Participant | D33: Total Housing Costs (LCU/month) | E33: # of rooms (total) | F33: Decent Housing Standard | G33: Cost per room (LCU/room/month) | H33: Comment
C34: Survey #1 | D34: {=TRANSPOSE('Background calculations'!C62:Q62)} -> 90000 | E34: {=TRANSPOSE('CLS - Input data'!D23:R23)} -> 3 | F34: =IFERROR(IF('Background calculations'!C43,"Met","Not met"),"") -> Met | G34: =IFERROR(IF('Background calculations'!C43,D34/E34,""),"") -> 30000 | H34: =IFERROR(IF('Background calculations'!S43="No","Participant has been excluded from study",IF('Background calculations'!M43=FALSE,"Decent housing mandatory criteria not met",IF('Background calculations'!R43=FALSE,"Missing 2 or more decent housing 'additional' criteria",""))),"")
C35: Survey #2 | D35: 140500 | E35: 2 | F35: =IFERROR(IF('Background calculations'!C44,"Met","Not met"),"") -> Met | G35: =IFERROR(IF('Background calculations'!C44,D35/E35,""),"") -> 70250 | H35: =IFERROR(IF('Background calculations'!S44="No","Participant has been excluded from study",IF('Background calculations'!M44=FALSE,"Decent housing mandatory criteria not met",IF('Background calculations'!R44=FALSE,"Missing 2 or more decent housing 'additional' criteria",""))),"")
C36: Survey #3 | D36: 151000 | E36: 3 | F36: =IFERROR(IF('Background calculations'!C45,"Met","Not met"),"") -> Met | G36: =IFERROR(IF('Background calculations'!C45,D36/E36,""),"") -> 50333.333 | H36: =IFERROR(IF('Background calculations'!S45="No","Participant has been excluded from study",IF('Background calculations'!M45=FALSE,"Decent housing mandatory criteria not met",IF('Background calculations'!R45=FALSE,"Missing 2 or more decent housing 'additional' criteria",""))),"")
C37: Survey #4 | D37: 111500 | E37: 3 | F37: =IFERROR(IF('Background calculations'!C46,"Met","Not met"),"") -> Met | G37: =IFERROR(IF('Background calculations'!C46,D37/E37,""),"") -> 37166.667 | H37: =IFERROR(IF('Background calculations'!S46="No","Participant has been excluded from study",IF('Background calculations'!M46=FALSE,"Decent housing mandatory criteria not met",IF('Background calculations'!R46=FALSE,"Missing 2 or more decent housing 'additional' criteria",""))),"")
C38: Survey #5 | D38: 119000 | E38: 2 | F38: =IFERROR(IF('Background calculations'!C47,"Met","Not met"),"") -> Met | G38: =IFERROR(IF('Background calculations'!C47,D38/E38,""),"") -> 59500 | H38: =IFERROR(IF('Background calculations'!S47="No","Participant has been excluded from study",IF('Background calculations'!M47=FALSE,"Decent housing mandatory criteria not met",IF('Background calculations'!R47=FALSE,"Missing 2 or more decent housing 'additional' criteria",""))),"")
C39: Survey #6 | D39: 150990 | E39: 3 | F39: =IFERROR(IF('Background calculations'!C48,"Met","Not met"),"") -> Met | G39: =IFERROR(IF('Background calculations'!C48,D39/E39,""),"") -> 50330 | H39: =IFERROR(IF('Background calculations'!S48="No","Participant has been excluded from study",IF('Background calculations'!M48=FALSE,"Decent housing mandatory criteria not met",IF('Background calculations'!R48=FALSE,"Missing 2 or more decent housing 'additional' criteria",""))),"")
C40: Survey #7 | D40: 86500 | E40: 3 | F40: =IFERROR(IF('Background calculations'!C49,"Met","Not met"),"") -> Met | G40: =IFERROR(IF('Background calculations'!C49,D40/E40,""),"") -> 28833.333 | H40: =IFERROR(IF('Background calculations'!S49="No","Participant has been excluded from study",IF('Background calculations'!M49=FALSE,"Decent housing mandatory criteria not met",IF('Background calculations'!R49=FALSE,"Missing 2 or more decent housing 'additional' criteria",""))),"")
C41: Survey #8 | D41: 118000 | E41: 2 | F41: =IFERROR(IF('Background calculations'!C50,"Met","Not met"),"") -> Met | G41: =IFERROR(IF('Background calculations'!C50,D41/E41,""),"") -> 59000 | H41: =IFERROR(IF('Background calculations'!S50="No","Participant has been excluded from study",IF('Background calculations'!M50=FALSE,"Decent housing mandatory criteria not met",IF('Background calculations'!R50=FALSE,"Missing 2 or more decent housing 'additional' criteria",""))),"")
C42: Survey #9 | D42: 162010 | E42: 2 | F42: =IFERROR(IF('Background calculations'!C51,"Met","Not met"),"") -> Met | G42: =IFERROR(IF('Background calculations'!C51,D42/E42,""),"") -> 81005 | H42: =IFERROR(IF('Background calculations'!S51="No","Participant has been excluded from study",IF('Background calculations'!M51=FALSE,"Decent housing mandatory criteria not met",IF('Background calculations'!R51=FALSE,"Missing 2 or more decent housing 'additional' criteria",""))),"")
C43: Survey #10 | D43: 171500 | E43: 3 | F43: =IFERROR(IF('Background calculations'!C52,"Met","Not met"),"") -> Met | G43: =IFERROR(IF('Background calculations'!C52,D43/E43,""),"") -> 57166.667 | H43: =IFERROR(IF('Background calculations'!S52="No","Participant has been excluded from study",IF('Background calculations'!M52=FALSE,"Decent housing mandatory criteria not met",IF('Background calculations'!R52=FALSE,"Missing 2 or more decent housing 'additional' criteria",""))),"")
C44: Survey #11 | D44: 128167 | E44: 2 | F44: =IFERROR(IF('Background calculations'!C53,"Met","Not met"),"") -> Met | G44: =IFERROR(IF('Background calculations'!C53,D44/E44,""),"") -> 64083.5 | H44: =IFERROR(IF('Background calculations'!S53="No","Participant has been excluded from study",IF('Background calculations'!M53=FALSE,"Decent housing mandatory criteria not met",IF('Background calculations'!R53=FALSE,"Missing 2 or more decent housing 'additional' criteria",""))),"")
C45: Survey #12 | D45: 255000 | E45: 3 | F45: =IFERROR(IF('Background calculations'!C54,"Met","Not met"),"") -> Met | G45: =IFERROR(IF('Background calculations'!C54,D45/E45,""),"") -> 85000 | H45: =IFERROR(IF('Background calculations'!S54="No","Participant has been excluded from study",IF('Background calculations'!M54=FALSE,"Decent housing mandatory criteria not met",IF('Background calculations'!R54=FALSE,"Missing 2 or more decent housing 'additional' criteria",""))),"")
C46: Survey #13 | D46: 80600 | E46: 3 | F46: =IFERROR(IF('Background calculations'!C55,"Met","Not met"),"") -> Met | G46: =IFERROR(IF('Background calculations'!C55,D46/E46,""),"") -> 26866.667 | H46: =IFERROR(IF('Background calculations'!S55="No","Participant has been excluded from study",IF('Background calculations'!M55=FALSE,"Decent housing mandatory criteria not met",IF('Background calculations'!R55=FALSE,"Missing 2 or more decent housing 'additional' criteria",""))),"")
... C48: Survey #15 | D48: 111680 | E48: 2 | F48: =IFERROR(IF('Background calculations'!C57,"Met","Not met"),"") -> Met | G48: =IFERROR(IF('Background calculations'!C57,D48/E48,""),"") -> 55840 | H48: =IFERROR(IF('Background calculations'!S57="No","Participant has been excluded from study",IF('Background calculations'!M57=FALSE,"Decent housing mandatory criteria not met",IF('Background calculations'!R57=FALSE,"Missing 2 or more decent housing 'additional' criteria",""))),"")
F50: Estimated Cost per Room (average) | G50: =IFERROR(AVERAGE(G34:G48,1),"") -> 49148.51

Sheet Decent housing
A2: Estimating housing costs
B4: ASSESS LOCAL DECENT HOUSING STANDARD
B6: Guidance
B7: In this tab, the user needs to provide the minimum level of decency for the 8 criteria (cells D10-D19). These critieria will be used by the user to assess if a house meets the decency standard. 1) Mandatory criteria (cells D10-D13): do not edit those criteria. Those criteria are based on minimum international standards and are assumed to be fixed 2) Additional criteria (cells D16-D19): Instert the criteria that are specific for the study. In order to define an appropriate minimum local decent standard for the region of your study, you can refer to the guidance provided in the Local Decent Housing Standard Guideline document.
B9: Mandatory criteria | D9: Minimum local decent standard
B10: Living space | D10: 2 or less persons per room excluding kitchen and toilet and bath. However, could be one big room of at least 30 square meters for a family of 5 (minimum 6 square meters per person)
B11: Durable walls structure: permanent material (e.g. brick, cement, Stone, well-joined walls) | D11: The minimum standard is to have permanent walls. Accepted: Brick/cement/stone/well-joined walls Unaccepted: Mud, mud with Stone, sticks, bamboo or iron sheets are unacceptable. Wood-walls is unacceptable in case of high risks of hurricanes in the region
B12: Durable roof structure: permanent material (e.g. zinc or iron sheet, corrugated iron, cement, tile roof) | D12: The minimum standard is to have permanent roof without leaks. Accepted: Zinc or iron sheet/corrugated iron/ cement/tile roof Unaccepted: Thatch is unacceptable
B13: Durable floor structure: permanent material (e.g. cement, Stone, tile, Wood) | D13: The minimum standard is to have permanent floor above ground. Accepted: Cement/stone/tile/wood floor Unaccepted: Mud, earth/dung, thatch
B15: Additional criteria | D15: Minimum local decent standard | I15: Instructions
B16: Toilet: Safe toilet in or outside the house (at least pit latrine with slab and walls) | D16: Safe toilet in or near house. Unaccepted: Pit latrine without slab or open pit is unacceptable We consider pit latrine with slab minimum acceptable | I16: Minimum local decency standard level can changes between different countries (e.g. based on the level of development of the country or cultural differences). Even within the same country, minimum local decency standards might vary depending on the zone (e.g. rural vs urban areas). To define a minimum local decency standard that fits the region of the study for the Additional criteria (cells D16-D19), please review the guidance provided in the Local Decent Housing Standard Guideline document. In that document, there are already pre-defined minimum criteria for the three zones (urban, peri-urban, and rural) that can be used as reference for each study.
B17: Access to water | D17: Safe water in or near house. Unprotected wells are unacceptable. Walking distance from water source <3km River water is okay for shower or other use, but not acceptable for drinking.
B18: Adequate cooking facility - separate kitchen with adequate evacuation of fumes if cooking indoors (chimney or window in the kitchen) | D18: Cooking can be done outside the house, if indoors adequate ventilation required if kitchen is inside house (minimum of a window in the kitchen)
B19: Availability of electricity (for lighting or indoor climate control) | D19: Grid may not be available. Access to electricity or alternative fuels to provide at least adequate lighting.
B21: Guidance
B22: In rows 27-34, the user needs to specify whether the interviewed individuals meet the defined criteria for decent housing defined above. To answers those questions (Yes or No in a dropdown menu), the user must consult the answers from the Cost of Living Survey. Cells B27-B34 provide an indication of where you can find the information in the Cost of Living Survey that will be needed to answer the question. Cells V27-V34 (do not edit) are the criteria that needs to be met (defined in the section above) Please answer "Yes" if the house of the participant meets that minimum criteria, and "No" if it does not meet that criteria. Based on the answers inserted by the user, the tool will automatically calculate if a participant meets the local standards for decent housing. Example: For instance, if the criteria for Durable Wall structure is "to have permanent walls materials such as brick, cement, and stone", in the case that a participant has a wall made of mud, the user must select "No" in row 28 for that specific participant
B24: Does the participants meet the following criteria?
E25: Participants
E26: 1 | F26: 2 | G26: 3 | H26: 4 | I26: 5 | J26: 6 | K26: 7 | L26: 8 | M26: 9 | N26: 10 | O26: 11 | P26: 12 | Q26: 13 | R26: 14 | S26: 15 | U26: Guidance
B27: Do you consider the participant eligible for the study? | E27: Yes | F27: Yes | G27: Yes | H27: Yes | I27: Yes | J27: Yes | K27: Yes | L27: Yes | M27: Yes | N27: Yes | O27: Yes | P27: Yes | Q27: Yes | R27: Yes | S27: Yes | U27: Exclude from the study individuals living in their place of work or temporary accomodation (e.g. hotel room)
B28: 4. Durable structure (materials) | C28: Materials used for walls | D28: Durable walls | E28: Yes | F28: Yes | G28: Yes | H28: Yes | I28: Yes | J28: Yes | K28: Yes | L28: Yes | M28: Yes | N28: Yes | O28: Yes | P28: Yes | Q28: Yes | R28: Yes | S28: Yes | U28: Does the house of the participant meet the following criteria: | V28: =D11 -> The minimum standard is to have permanent walls. Accepted: Brick/cement/stone/well-joined walls Unaccepted: Mud, mud with Stone, sticks, bamboo or iron sheets are unacceptable. Wood-walls is unacceptable in case of high risks of hurricanes in the region
B29: 4. Durable structure (materials) | C29: Materials used for roof | D29: Durable roof | E29: Yes | F29: Yes | G29: Yes | H29: Yes | I29: Yes | J29: Yes | K29: Yes | L29: Yes | M29: Yes | N29: Yes | O29: Yes | P29: Yes | Q29: Yes | R29: Yes | S29: Yes | U29: Does the house of the participant meet the following criteria: | V29: =D12 -> The minimum standard is to have permanent roof without leaks. Accepted: Zinc or iron sheet/corrugated iron/ cement/tile roof Unaccepted: Thatch is unacceptable
B30: 4. Durable structure (materials) | C30: Materials used for floors | D30: Durable floor | E30: Yes | F30: Yes | G30: Yes | H30: Yes | I30: Yes | J30: Yes | K30: Yes | L30: Yes | M30: Yes | N30: Yes | O30: Yes | P30: Yes | Q30: Yes | R30: Yes | S30: Yes | U30: Does the house of the participant meet the following criteria: | V30: =D13 -> The minimum standard is to have permanent floor above ground. Accepted: Cement/stone/tile/wood floor Unaccepted: Mud, earth/dung, thatch
B31: 5. Safe sanitation | C31: Does the household meet the minimum decency criteria? | D31: Safe sanitation? | E31: Yes | F31: Yes | G31: Yes | H31: Yes | I31: Yes | J31: Yes | K31: Yes | L31: Yes | M31: Yes | N31: Yes | O31: Yes | P31: Yes | Q31: Yes | R31: Yes | S31: Yes | U31: Does the house of the participant meet the following criteria: | V31: =D16 -> Safe toilet in or near house. Unaccepted: Pit latrine without slab or open pit is unacceptable We consider pit latrine with slab minimum acceptable
B32: 6. Access to water | C32: Does the household meet the minimum decency criteria? | D32: Access to water | E32: Yes | F32: Yes | G32: Yes | H32: Yes | I32: Yes | J32: Yes | K32: Yes | L32: Yes | M32: Yes | N32: Yes | O32: Yes | P32: Yes | Q32: Yes | R32: Yes | S32: Yes | U32: Does the house of the participant meet the following criteria: | V32: =D17 -> Safe water in or near house. Unprotected wells are unacceptable. Walking distance from water source <3km River water is okay for shower or other use, but not acceptable for drinking.
B33: 7. Adequate coocking facility | C33: Does the household meet the minimum decency criteria? | D33: Adequate cooking facility | E33: Yes | F33: Yes | G33: Yes | H33: Yes | I33: Yes | J33: Yes | K33: Yes | L33: Yes | M33: Yes | N33: Yes | O33: Yes | P33: Yes | Q33: Yes | R33: Yes | S33: Yes | U33: Does the house of the participant meet the following criteria: | V33: =D18 -> Cooking can be done outside the house, if indoors adequate ventilation required if kitchen is inside house (minimum of a window in the kitchen)
B34: 8. Energy sources | C34: Does the household meet the minimum decency criteria? | D34: Access to electricity | E34: Yes | F34: Yes | G34: Yes | H34: Yes | I34: Yes | J34: Yes | K34: Yes | L34: Yes | M34: Yes | N34: Yes | O34: Yes | P34: Yes | Q34: Yes | R34: Yes | S34: Yes | U34: Does the house of the participant meet the following criteria: | V34: =D19 -> Grid may not be available. Access to electricity or alternative fuels to provide at least adequate lighting.

Sheet 3. Food costs
B2: Estimating food costs
B4: 1) ESTIMATE FOOD COSTS FOR REFERENCE SIZE FAMILY
B6: Guidance
B7: This tab provides the results of the Food cost analysis. Do not edit cells and tables rin this tab
C10: FOOD COSTS
C12: Results for Reference Household Size
E13: LCU/month | G13: USD/month
C14: Monthly Household Food Cost | E14: =IFERROR(SUMPRODUCT('Background calculations'!D134:D136,'3. Food costs'!E25:E27),"")-(D95*E27) -> 648047.94 | G14: =IFERROR(E14/'OUTPUT_Living wage'!E10,"") -> 176.33958
C17: Model diet cost for one adult (male) | E17: LCU/adult male/day | G17: USD/adult male/day
C18: Estimated Daily Cost | E18: ='3. Food costs'!D75 -> 6414.5633 | G18: =IFERROR(E18/'OUTPUT_Living wage'!$E$10,"") -> 1.7454594
E20: LCU/adult male/month | G20: USD/adult male/month
C21: Monthly Food Cost | E21: =E18*30.43 -> 195195.16 | G21: =IFERROR(E21/'OUTPUT_Living wage'!$E$10,"") -> 53.11433
C23: Houshold Composition
D24: Selected | E24: ='OUTPUT_Living wage'!E15 -> Personalized
C25: Adult (male) | D25: total # in household | E25: ='Background calculations'!G10 -> 1 | G25: =E25 -> 1
C26: Adult (female) | D26: total # in household | E26: ='Background calculations'!G11 -> 1 | G26: =E26 -> 1
C27: Children | D27: total # in household | E27: ='Background calculations'!G12 -> 2 | G27: =E27 -> 2
C31: ENERGY CONSUMPTION & NUTRITIONAL TARGETS | H31: Guidance
H32: The Energy consumption target (cell D35) can be adjusted by modifyig the minimum and maximum amounts for food items of the model diet (Section 1C of the "Nutritional input" tab, rows 96-114). The calculated value (cell E35) will turn red if the target value (cell D35) is not met (a 1% error margin is allowed)
D33: Target | E33: Calculated
C35: Energy consumption target (kCal) | D35: ='Nutritional input'!E16 -> 2767.1366 | E35: =SUM('Background calculations'!AC216:AC234) -> 2767.9707
C37: Energy from Carbohydrates | D37: 55 - 75 % | E37: ='Background calculations'!D243 -> 0.60567382
C38: Energy from fats | D38: 15 - 30 % | E38: ='Background calculations'!F243 -> 0.28878968
C39: Energy from proteins | E39: ='Background calculations'!E243 -> 0.1055365
C41: Energy from high quality proteins food items* | D41: >10% | E41: =IFERROR(('Background calculations'!AC220+'Background calculations'!AC221+'Background calculations'!AC224+ 'Background calculations'!AC225) / E35,"") -> 0.19979258
C42: *Pulses, legumes, beans and animal based proteins
C46: MODEL DIET
C48: Item | D48: Quantity edible portion (grams/day) | E48: Quantity to purchase (grams/day) | F48: Price (LCU/day)
C49: ='Nutritional input'!D112 -> Rice 2 | D49: ='Background calculations'!AB216 -> 289.86131 | E49: =D49/_xlfn.XLOOKUP(C49,Table2[Item],Table2[Edible portion]) -> 289.86131 | F49: =_xlfn.XLOOKUP('3. Food costs'!C49,'Food costs - Input data'!C11:C59,'Food costs - Input data'!AE11:AE59,0) / 1000 * '3. Food costs'!E49 -> 1159.4452
C50: ='Nutritional input'!D113 -> Bread | D50: ='Background calculations'!AB217 -> 68.199851 | E50: =D50/_xlfn.XLOOKUP(C50,Table2[Item],Table2[Edible portion]) -> 68.199851 | F50: =_xlfn.XLOOKUP('3. Food costs'!C50,'Food costs - Input data'!C12:C60,'Food costs - Input data'!AE12:AE60,0) / 1000 * '3. Food costs'!E50 -> 375.09918
C51: ='Nutritional input'!D114 -> Cassava | D51: ='Background calculations'!AB218 -> 236.12455 | E51: =D51/_xlfn.XLOOKUP(C51,Table2[Item],Table2[Edible portion]) -> 295.15569 | F51: =_xlfn.XLOOKUP('3. Food costs'!C51,'Food costs - Input data'!C13:C61,'Food costs - Input data'!AE13:AE61,0) / 1000 * '3. Food costs'!E51 -> 590.31138
C52: ='Nutritional input'!D115 -> Matooke | D52: ='Background calculations'!AB219 -> 160 | E52: =D52/_xlfn.XLOOKUP(C52,Table2[Item],Table2[Edible portion]) -> 200 | F52: =_xlfn.XLOOKUP('3. Food costs'!C52,'Food costs - Input data'!C14:C62,'Food costs - Input data'!AE14:AE62,0) / 1000 * '3. Food costs'!E52 -> 160
C53: ='Nutritional input'!D116 -> Groundnuts | D53: ='Background calculations'!AB220 -> 41.463411 | E53: =D53/_xlfn.XLOOKUP(C53,Table2[Item],Table2[Edible portion]) -> 51.829264 | F53: =_xlfn.XLOOKUP('3. Food costs'!C53,'Food costs - Input data'!C15:C63,'Food costs - Input data'!AE15:AE63,0) / 1000 * '3. Food costs'!E53 -> 285.06095
C54: ='Nutritional input'!D117 -> Groundnuts | D54: ='Background calculations'!AB221 -> 41.463411 | E54: =D54/_xlfn.XLOOKUP(C54,Table2[Item],Table2[Edible portion]) -> 51.829264 | F54: =_xlfn.XLOOKUP('3. Food costs'!C54,'Food costs - Input data'!C16:C64,'Food costs - Input data'!AE16:AE64,0) / 1000 * '3. Food costs'!E54 -> 285.06095
C55: ='Nutritional input'!D118 -> Youghurt | D55: ='Background calculations'!AB222 -> 60 | E55: =D55/_xlfn.XLOOKUP(C55,Table2[Item],Table2[Edible portion]) -> 66.666667 | F55: =_xlfn.XLOOKUP('3. Food costs'!C55,'Food costs - Input data'!C17:C65,'Food costs - Input data'!AE17:AE65,0) / 1000 * '3. Food costs'!E55 -> 100
C56: ='Nutritional input'!D119 -> Eggs | D56: ='Background calculations'!AB223 -> 28.883063 | E56: =D56/_xlfn.XLOOKUP(C56,Table2[Item],Table2[Edible portion]) -> 32.092292 | F56: =_xlfn.XLOOKUP('3. Food costs'!C56,'Food costs - Input data'!C18:C66,'Food costs - Input data'!AE18:AE66,0) / 1000 * '3. Food costs'!E56 -> 385.1075
C57: ='Nutritional input'!D120 -> beef | D57: ='Background calculations'!AB224 -> 14.791082 | E57: =D57/_xlfn.XLOOKUP(C57,Table2[Item],Table2[Edible portion]) -> 24.651803 | F57: =_xlfn.XLOOKUP('3. Food costs'!C57,'Food costs - Input data'!C19:C67,'Food costs - Input data'!AE19:AE67,0) / 1000 * '3. Food costs'!E57 -> 468.38425
C58: ='Nutritional input'!D121 -> Ngege Fresh | D58: ='Background calculations'!AB225 -> 12 | E58: =D58/_xlfn.XLOOKUP(C58,Table2[Item],Table2[Edible portion]) -> 20 | F58: =_xlfn.XLOOKUP('3. Food costs'!C58,'Food costs - Input data'!C20:C68,'Food costs - Input data'!AE20:AE68,0) / 1000 * '3. Food costs'!E58 -> 200
C59: ='Nutritional input'!D122 -> Sukuma | D59: ='Background calculations'!AB226 -> 100 | E59: =D59/_xlfn.XLOOKUP(C59,Table2[Item],Table2[Edible portion]) -> 100 | F59: =_xlfn.XLOOKUP('3. Food costs'!C59,'Food costs - Input data'!C21:C69,'Food costs - Input data'!AE21:AE69,0) / 1000 * '3. Food costs'!E59 -> 100
C60: ='Nutritional input'!D123 -> Doodo | D60: ='Background calculations'!AB227 -> 60 | E60: =D60/_xlfn.XLOOKUP(C60,Table2[Item],Table2[Edible portion]) -> 60 | F60: =_xlfn.XLOOKUP('3. Food costs'!C60,'Food costs - Input data'!C22:C70,'Food costs - Input data'!AE22:AE70,0) / 1000 * '3. Food costs'!E60 -> 60
...

Sheet CLS - Input data
A3: Estimating housing costs
A5: 1B) HOUSING COSTS FOR REFERENCE HOUSEHOLD SIZE
A7: Guidance
A8: In this tab, the user needs to insert the data collected from the Cost of Living Survey. The data will be used by the tool to estimate the cost for decent housing
A9: The information in Row 16to Row 33 must be retrieved from the results of the Cost of Living Survey. - Column B tells you in which section of the Cost of Living Survey you can find that information. - Column C provides an additional description of the question related to that data point - Column D provides the short definition of the datapoint to be reported in this tab IMPORTANT: All cost-related data (row 26 to row 33) must be provided in LCU (local currency) per month.
D14: Participants
A15: Section in Survey | B15: Question from Survey / note | C15: Line item | D15: 1 | E15: 2 | F15: 3 | G15: 4 | H15: 5 | I15: 6 | J15: 7 | K15: 8 | L15: 9 | M15: 10 | N15: 11 | O15: 12 | P15: 13 | Q15: 14 | R15: 15
A16: 2. Household characteristics | B16: What is the age of the participant? / When were you born? | C16: Age | D16: 60 | E16: 35 | F16: 42 | G16: 56 | H16: 43 | I16: 56 | J16: 28 | K16: 32 | L16: 33 | M16: 54 | N16: 38 | O16: 59 | P16: 54 | Q16: 37 | R16: 71
A17: 2. Household characteristics | B17: What is the gender of the participant? | C17: Gender | D17: M | E17: F | F17: M | G17: F | H17: F | I17: M | J17: M | K17: F | L17: F | M17: M | N17: M | O17: F | P17: F | Q17: F | R17: M
A18: 2. Household characteristics | B18: How many people live in the house (permanently)? | C18: Household size | D18: 4 | E18: 4 | F18: 4 | G18: 4 | H18: 4 | I18: 4 | J18: 4 | K18: 4 | L18: 4 | M18: 4 | N18: 4 | O18: 4 | P18: 4 | Q18: 4 | R18: 4
A19: 2. Household characteristics | B19: How many adults live in the family? | C19: Adults in Household | D19: 2 | E19: 2 | F19: 2 | G19: 2 | H19: 2 | I19: 2 | J19: 2 | K19: 2 | L19: 2 | M19: 2 | N19: 2 | O19: 2 | P19: 2 | Q19: 2 | R19: 2
A20: 2. Household characteristics | B20: Number of full-time workers in the family | C20: Identified as full-time working adults | D20: 2 | E20: 2 | F20: 2 | G20: 2 | H20: 2 | I20: 1 | J20: 2 | K20: 1 | L20: 2 | M20: 2 | N20: 2 | O20: 2 | P20: 2 | Q20: 2 | R20: 2
A21: 2. Household characteristics | B21: Number of part-time workers in the family | C21: Identified as part-time working adults | D21: 0 | E21: 0 | F21: 0 | G21: 0 | H21: 0 | I21: 1 | J21: 0 | K21: 1 | L21: 0 | M21: 0 | N21: 0 | O21: 0 | P21: 0 | Q21: 0 | R21: 0
A22: 2. Household characteristics | B22: Number of children | C22: Number of children | D22: 3 | E22: 4 | F22: 2 | G22: 3 | H22: 4 | I22: 3 | J22: 5 | K22: 2 | L22: 4 | M22: 4 | N22: 5 | O22: 0 | P22: 3 | Q22: 3 | R22: 6
A23: 3. House structure | B23: Total number of rooms (only living rooms and bedrooms) | C23: Number of rooms | D23: 3 | E23: 2 | F23: 3 | G23: 3 | H23: 2 | I23: 3 | J23: 3 | K23: 2 | L23: 2 | M23: 3 | N23: 2 | O23: 3 | P23: 3 | Q23: 3 | R23: 2
A24: 3. House structure | B24: Total surface | C24: Total space (sq mt) | D24: 25.08 | E24: 40.25 | F24: 44.59 | G24: 66.89 | H24: 80.3 | I24: 66.89 | J24: 50.15 | K24: 29.73 | L24: 45.52 | M24: 91.97 | N24: 88.26 | O24: 55.74 | P24: 74.32 | Q24: 27.87 | R24: 67.16
A26: 9. Housing costs | B26: How much do you pay for rent? | C26: Rent (LCU / month) | D26: 60000 | E26: 60000 | F26: 70000 | G26: 50000 | H26: 50000 | I26: 30000 | J26: 25000 | K26: 40000 | L26: 40000 | M26: 100000 | N26: 40000 | O26: 150000 | P26: 20000 | Q26: 30000 | R26: 50000
A27: 6. Access to water | B27: How much do you pay for water? | C27: Water (LCU / month) | D27: 0 | E27: 10500 | F27: 9000 | G27: 1500 | H27: 9000 | I27: 990 | J27: 1500 | K27: 18000 | L27: 2010 | M27: 1500 | N27: 1500 | O27: 45000 | P27: 600 | Q27: 3000 | R27: 1680
A28: 8. Energy sources | B28: How much do you pay for electricity (either grid or fuels or both) | C28: Electricity (LCU / month) | D28: 0 | E28: 10000 | F28: 12000 | G28: 0 | H28: 0 | I28: 0 | J28: 0 | K28: 0 | L28: 0 | M28: 0 | N28: 26667 | O28: 0 | P28: 0 | Q28: 0 | R28: 0
A29: 7. Adequate coocking facility | B29: How much do you pay for cooking fuel? | C29: Cooking fuel (LCU / month) | D29: 30000 | E29: 60000 | F29: 60000 | G29: 60000 | H29: 60000 | I29: 120000 | J29: 60000 | K29: 60000 | L29: 120000 | M29: 70000 | N29: 60000 | O29: 60000 | P29: 60000 | Q29: 60000 | R29: 60000
A31: 11. Non-food, Non-housing costs | B31: How much do you pay for healthcare? | C31: Healthcare (LCU / month) | D31: 0 | E31: 26667 | F31: 0 | G31: 0 | H31: 0 | I31: 0 | J31: 0 | K31: 0 | L31: 0 | M31: 0 | N31: 26667 | O31: 0 | P31: 33333 | Q31: 0 | R31: 26667
... A33: 11. Non-food, Non-housing costs | B33: How much do you pay for transporation? | C33: Transport (LCU / month) | D33: 82000 | E33: 30000 | F33: 20000 | G33: 4000 | H33: 0 | I33: 28000 | J33: 40000 | K33: 2000 | L33: 10000 | M33: 0 | N33: 30000 | O33: 0 | P33: 70000 | Q33: 12000 | R33: 12000

Sheet Food costs - Input data
C3: Estimating food costs
B5: Guidance | AB5: IF MORE THAN 25 PRICES ARE COLLECTED FOR A FOOD ITEM, INSERT A NEW COLUMN BEFORE COLUMN AB AND MAKE SURE THAT THE FORMULA FOR THE LOWEST PRICE IS STILL IN RANGE
B6: In this tab, you need to insert the list of food items included in the study and the data collected from the Food Price Survey. The data will be used by the tool to estimate the cost for decent housing. Make sure that all the data you insert are provided in LCU/kg Actions required: 1) Insert the food items included in the study in Column C. 2) Insert the food prices collected during the survey IMPORTANT: Do not edit column B or add any additional row
AE9: From data collected via surveys
B10: Category | C10: Item | D10: Price 1 | E10: Price 2 | F10: Price 3 | G10: Price 4 | H10: Price 5 | I10: Price 6 | J10: Price 7 | K10: Price 8 | L10: Price 9 | M10: Price 10 | N10: Price 11 | O10: Price 12 | P10: Price 13 | Q10: Price 14 | R10: Price 15 | S10: Price 16 | T10: Price 17 | U10: Price 18 | V10: Price 19 | W10: Price 20 | X10: Price 21 | Y10: Price 22 | Z10: Price 23 | AA10: Price 24 | AB10: Price 25 | AE10: Lowest price | AF10: Average | AG10: Median | AH10: Minimum | AI10: Average
B11: Cereals and Grains | C11: Rice 1 | D11: 4500 | E11: 3000 | F11: 3500 | AE11: =MIN(D11:AB11) -> 3000 | AF11: Check these for comparison
B12: Cereals and Grains | C12: Rice 2 | D12: 4000 | E12: 4000 | F12: 4000 | AE12: =MIN(D12:AB12) -> 4000
B13: Cereals and Grains | C13: Rice 3 | D13: 5500 | E13: 5500 | F13: 5500 | AE13: =MIN(D13:AB13) -> 5500
B14: Cereals and Grains | C14: Rice 4 | D14: 4000 | E14: 4000 | F14: 4000 | AE14: =MIN(D14:AB14) -> 4000
B15: Prepared cereals | C15: Bread | D15: 6500 | E15: 5500 | F15: 5500 | AE15: =MIN(D15:AB15) -> 5500
B16: Prepared cereals | C16: chapati | D16: 5000 | E16: 5000 | F16: 5000 | AE16: =MIN(D16:AB16) -> 5000
B17: Prepared cereals | C17: Doughnut | D17: 6000 | E17: 3000 | F17: 3000 | AE17: =MIN(D17:AB17) -> 3000
B18: Roots & tubers (starchy) | C18: Cassava | D18: 2000 | E18: 2000 | F18: 2000 | AE18: =MIN(D18:AB18) -> 2000
B19: Roots & tubers (starchy) | C19: Potatoes | D19: 3000 | E19: 3000 | F19: 3000 | AE19: =MIN(D19:AB19) -> 3000
B20: Roots & tubers (starchy) | C20: Yams | D20: 10000 | E20: 10000 | F20: 10000 | AE20: =MIN(D20:AB20) -> 10000
B21: Starchy fruit or vegetable | C21: Pumpkin | D21: 6000 | E21: 6000 | F21: 6000 | AE21: =MIN(D21:AB21) -> 6000
B22: Starchy fruit or vegetable | C22: Matooke | D22: 800 | E22: 800 | F22: 800 | AE22: =MIN(D22:AB22) -> 800
B23: Starchy fruit or vegetable | C23: Green Pepper | D23: 6000 | E23: 1000 | F23: 1000 | AE23: =MIN(D23:AB23) -> 1000
... B63: Other | C63: Non Alcoholic Kombucha | D63: 1000 | E63: 1500 | F63: 1000 | AE63: =MIN(D63:AB63) -> 1000

Sheet Nutritional input
A2: Estimating food costs
B4: Guidance
B5: In the tab, the user must provide nutrition-related information that is needed to estimate the food for a low-cost nutritious diet. Section 1A: In this section the user must provide basic information needed to calculate the Energy Consumption target for an adult male (daily calorie intake) Section 1B: In this section you will need to provide nutritional information regarding the food items included in the study Section 1C: In this section you will insert the quantity of food to be consumed in the model diet for each of the food items (instructions and suggestions are provided in the section) IMPORTANT: . Do not add any new row in this tab. The food items in Column D will be automatically inserted based on the input provided in the previous tab
B7: 1A) Calculate the energy consumption requirement
C9: ENERGY CONSUMPTION TARGET | K9: Source | L9: Instructions
E11: Male | G11: Female
C12: Average height (meters) | E12: 1.6 | G12: 1.5 | K12: LINK | L12: "- Go to the link provided on the left. Under the section "Height surveys and studies" click "[show]" in the header row of the table and a list of average heights will appear. If available, gather the average male height for the country of study. If the average male height is not available, then collect the average female height. - In case the country is not listed in the source provided in cell K12, gather the average male height for the macro-region of the country of study from this link (section "Heights by continents")--> https://www.worlddata.info/average-bodyheight.php
C14: Activity Level (of adult male) | E14: Moderate | L14: Select the activity level for the adult male. Select "sedentary" for office-type jobs and "vigorous" for agricultural or heavy-type of work.
C16: Energy Consumption Target | D16: kcal/day | E16: =_xlfn.IFNA(HLOOKUP(E14,'Background calculations'!$E$124:$G$128,5,FALSE),"") -> 2767.1366
B19: 1B) Nutritional value of food
B21: Guidance
C22: In the table below (rows 30-66), the user must add the nutritional value of the different food items. The model requires the user to add the protein content, fat content, carbohydrate content and edible portion of each food item. The protein/fat/carbohydrate contents are provided in number of grams per 100 gram of food item. If the source provides the protein/fat/carbohydrate content in %, then you need to translate it to grams (e.g. 7% of fat content is 7 grams) To retrieve this information: Nutritional information can be found in the USDA data base (link provided below). For specific regional food items, go to the FAO info-food section and select the relevant region. Food content might vary per country. It is recommended that you collect nutritional values that are contry-specific. However, if that is not possible or if they are not available, it is ok to use nutritrional information gathered in previous studies for the same food items. IMPORTANT: Do not add any additional rows, nor columns or food items in the table below. The food items displayed below are automatically picked from the "Food costs - Input data" tab.
C23: Sources to retrieve nutritional information:
C24: https://reedir.arsnet.usda.gov/codesearchwebapp/(S(quhg4cjj0v0s2mbsualpdgns))/codesearch.aspx
C25: http://www.fao.org/infoods/infoods/tables-and-databases/africa/en/
C29: Category | D29: Item | E29: Protein (g) | F29: Fat, total (g) | G29: Carbohydrate (g) | H29: Edible portion
C30: ='Food costs - Input data'!B11 -> Cereals and Grains | D30: =IF('Food costs - Input data'!C11="","",'Food costs - Input data'!C11) -> Rice 1 | E30: 7.1 | F30: 0.6 | G30: 78.2 | H30: 0.2
C31: ='Food costs - Input data'!B12 -> Cereals and Grains | D31: =IF('Food costs - Input data'!C12="","",'Food costs - Input data'!C12) -> Rice 2 | E31: 7.1 | F31: 0.6 | G31: 78.2 | H31: 1
C32: ='Food costs - Input data'!B13 -> Cereals and Grains | D32: =IF('Food costs - Input data'!C13="","",'Food costs - Input data'!C13) -> Rice 3 | E32: 7.1 | F32: 0.6 | G32: 78.2 | H32: 1
C33: ='Food costs - Input data'!B14 -> Cereals and Grains | D33: =IF('Food costs - Input data'!C14="","",'Food costs - Input data'!C14) -> Rice 4 | E33: 7.1 | F33: 0.6 | G33: 78.2 | H33: 1
C34: ='Food costs - Input data'!B15 -> Prepared cereals | D34: =IF('Food costs - Input data'!C15="","",'Food costs - Input data'!C15) -> Bread | E34: 8.5 | F34: 3.3 | G34: 49 | H34: 1
C35: ='Food costs - Input data'!B16 -> Prepared cereals | D35: =IF('Food costs - Input data'!C16="","",'Food costs - Input data'!C16) -> chapati | E35: 9 | F35: 12 | G35: 45 | H35: 1
C36: ='Food costs - Input data'!B17 -> Prepared cereals | D36: =IF('Food costs - Input data'!C17="","",'Food costs - Input data'!C17) -> Doughnut | E36: 5 | F36: 25 | G36: 51 | H36: 1
C37: ='Food costs - Input data'!B18 -> Roots & tubers (starchy) | D37: =IF('Food costs - Input data'!C18="","",'Food costs - Input data'!C18) -> Cassava | E37: 1.4 | F37: 0.3 | G37: 38.1 | H37: 0.8
C38: ='Food costs - Input data'!B19 -> Roots & tubers (starchy) | D38: =IF('Food costs - Input data'!C19="","",'Food costs - Input data'!C19) -> Potatoes | E38: 2 | F38: 0.1 | G38: 17 | H38: 0.8
C39: ='Food costs - Input data'!B20 -> Roots & tubers (starchy) | D39: =IF('Food costs - Input data'!C20="","",'Food costs - Input data'!C20) -> Yams | E39: 1.5 | F39: 0.2 | G39: 27 | H39: 0.8
C40: ='Food costs - Input data'!B21 -> Starchy fruit or vegetable | D40: =IF('Food costs - Input data'!C21="","",'Food costs - Input data'!C21) -> Pumpkin | E40: 1 | F40: 0.1 | G40: 7 | H40: 0.8
C41: ='Food costs - Input data'!B22 -> Starchy fruit or vegetable | D41: =IF('Food costs - Input data'!C22="","",'Food costs - Input data'!C22) -> Matooke | E41: 0.9 | F41: 0.2 | G41: 10 | H41: 0.8
... C82: ='Food costs - Input data'!B63 -> Other | D82: =IF('Food costs - Input data'!C63="","",'Food costs - Input data'!C63) -> Non Alcoholic Kombucha | E82: 2 | F82: 1 | G82: 10 | H82: 1
B85: 1C) Refine model diet to meet WHO recommendations
C87: Guidance
C88: In this section, the user must provide values for the minimum and maximum amount of food for the model diet. Edit cells F96-F114 and Control if cells E83-E87 falls into ranges that are recommended by WHO (do not edit cells D83-D87). The calculated value (cell D83) will turn red if the target value (cell E83) is not met (a 1% error margin is allowed). If the target values are not met (rows 83-87), here there are some suggestions: - If Carbohydrates are too low: try to increase the minimum amount of cereals & grains, prepared cereals, and roots & tubers (starchy), or beans in cells F96-F114 - If fats are too low: try to increase the minimum amount of meat, fish, avocado (if there), eggs, or dairy in cells F96-F114 - If high-quality proteins are low: increase minimum intake of pulses, legumes, beans, and animal-based proteins (meat or fish) in cells F96-F114
C95: CALORY INTAKE and NUTRITIONAL CHECK
D97: ='3. Food costs'!D33 -> Target | E97: ='3. Food costs'!E33 -> Calculated
C99: Energy consumption target (kCal) | D99: ='3. Food costs'!D35 -> 2767.1366 | E99: ='Background calculations'!AC235 -> 2767.9707
C101: Energy from Carbohydrates | D101: 50% - 75% | E101: =IFERROR('3. Food costs'!E37,"") -> 0.60567382
C102: Energy from fats | D102: ='3. Food costs'!D38 -> 15 - 30 % | E102: =IFERROR('3. Food costs'!E38,"") -> 0.28878968
C103: Energy from high quality proteins* | D103: >10% | E103: =IFERROR('3. Food costs'!E41,"") -> 0.19979258
C104: *Pulses, legumes, beans and animal based proteins
C109: Model Diet Intake
...

Sheet 4. NFNH costs
B2: Estimating non-food and non-housing costs
B4: 1) ESTIMATE NON-FOOD, NON-HOUSING COSTS
B6: Guidance
B8: Do not edit cells E16-E17
C11: NON-FOOD NON-HOUSING COSTS
D13: Unit | E13: Value
C15: Results for reference sized household
C16: Non-Food Non Housing cost | D16: LCU / household / month | E16: =IFERROR('Background calculations'!C300,"") -> 553120.92
C17: Non-Food Non Housing cost | D17: USD / household / month | E17: =IFERROR(E16/'OUTPUT_Living wage'!E10,"") -> 150.50909
B20: 1A) Input CPI weights
C22: CPI Weights
H23: Source | I23: Instruction
C24: Expenditure category | D24: National | E24: Regional | I24: For NFNH costs, you can decide if you want to use National or Region-specific information.
C25: Food and non-alcoholic beverages | D25: 0.45 | E25: 0.052
C26: Alcoholic Beverages, Tobacco, and Narcotics | D26: 0.03 | E26: 0.01 | H26: LINK | I26: For National information, you can collect the CPI Weights (data for cells D25-D37) from the IMF data bank to retrieve the national CPI weights
C27: Clothing and footwear | D27: 0.05 | E27: 0.02
C28: Housing, Water, Electricity, Gas and Other Fuels | D28: 0.104 | E28: 0.02 | I28: To increase the accuracy of the benchmark, if available, you can use region-specific CPI weights. There is no global database that contains regional CPI weights. Regional CPI weights can be retrieved from local goverenments agenices, national household survey reports or other localized reports.
C29: Furnishings, household equipment and routine household maintenance | D29: 0.03 | E29: 0.02
C30: Health | D30: 0.037 | E30: 0.04
C31: Transport | D31: 0.04 | E31: 0.03
C32: Communication | D32: 0.06 | E32: 0.03
C33: Recreation and culture | D33: 0.05 | E33: 0.01
C34: Education | D34: 0.018 | E34: 0.06
C35: Restaurants and hotels | D35: 0.067 | E35: 0.06
C36: Miscellaneous goods and services | D36: 0.023 | E36: 0.18
C37: Non-consumption expenditures | D37: 0.044 | E37: 0.02
C40: CPI Weights to use (national or regional) | D40: National | I40: IMPORTANT: Make sure that cell D40 displays the type of CPI weights you want to use for the model (National or Regional)

Sheet 5. Income tax
B2: Income tax
B5: 1) ESTIMATE INCOME TAXES
B7: Guidance
B8: solver expalanation
C11: Unit | D11: Value
B12: Monthly NET living wage | C12: LCU/month | D12: =+'OUTPUT_Living wage'!E35 -> 713873.14
B14: Annual NET living wage (which should be equal to the amount the would get from work) | C14: LCU/year | D14: =IFERROR(D12*12,"") -> 8566477.7
B17: Income tax based on NET | C17: LCU/year | D17: =IFERROR((D$14-INDEX($E$45:$E$53,MATCH(VLOOKUP(D$14,$C$46:$I$53,$I$44,1),$I$45:$I$53,0)))*VLOOKUP(D$14,$C$46:$I$53,$G$44,1)+INDEX($I$45:$I$53,MATCH(VLOOKUP(D$14,$C$46:$I$53,$I$44,1),$I$45:$I$53,0))+SUM(J46:J53),"") -> 819397.72
B19: Gross WAGE | C19: LCU/year | D19: 18095288 | E19: solver variable
B21: Annual income tax | C21: LCU/year | D21: =IFERROR((D$19-INDEX($E$45:$E$53,MATCH(VLOOKUP(D$19,$C$46:$I$53,$I$44,1),$I$45:$I$53,0)))*VLOOKUP(D$19,$C$46:$I$53,$G$44,1)+INDEX($I$45:$I$53,MATCH(VLOOKUP(D$19,$C$46:$I$53,$I$44,1),$I$45:$I$53,0))+SUM(J46:J53),"") -> 1772278.7
B23: Monthly incomre tax | C23: LCU/month | D23: =D21/12 -> 147689.9
B25: Solve to 0 | D25: =D19-D21-D14 -> 7756531.5 | E25: cell to solve --> value of 0 (highlight cell and run the solver add in)
B27: Tax rates | C27: Unit
B28: Marginal rate | C28: % | D28: =_xlfn.IFNA(VLOOKUP(D$19,$E$46:$I$53,3,1),"") -> 0.35
B29: Effective rate | C29: % | D29: =IFERROR(D21/D14,"") -> 0.20688535
D30: .
B33: 1A) Retrieve data on income taxes
B35: Guidance
B36: In the table below, you need to insert information on from tax autorities related to (1) taxable income levels (2) rates of taxations (3) low and high bound (4) tax rate (5) Fixed amount Use governamental sources to retrieve this information (e.g. governamental websites, governamental reports, etc)
B39: Sources
B40: Source 1
B41: Source 2
B44: General Tax | C44: 1 | D44: =C44+1 -> 2 | E44: =D44+1 -> 3 | F44: =E44+1 -> 4 | G44: =F44+1 -> 5 | H44: =G44+1 -> 6 | I44: =H44+1 -> 7 | J44: =I44+1 -> 8 | K44: 9
B45: ​Taxable income bands (text) | C45: Low bound | D45: High bound | E45: Income | F45: Taxable income | G45: Tax rate | H45: Taxed amount | I45: Cumulative tax | J45: Fixed amount | K45: Description / Source
B46: =+"From LCU "&C46&" to LCU "&D46 -> From LCU 235001 to LCU 335000 | C46: 235001 | D46: 335000 | E46: =C46 -> 235001 | F46: =IF($D$19<C46,0,IF($D$19>D46,D46-C46,$D$19-C46)) -> 99999 | G46: 0 | H46: =IF($D$19<C46,0,IF($D$19>D46,F46*G46,($D$19-C46)*G46)) -> 0 | I46: 0
B47: =+"From LCU "&C47&" to LCU "&D47 -> From LCU 335001 to LCU 410000 | C47: 335001 | D47: 410000 | E47: =D46 -> 335000 | F47: =IF($D$19<C47,0,IF($D$19>D47,D47-C47,$D$19-C47)) -> 74999 | G47: 0.05 | H47: =IF($D$19<C47,0,IF($D$19>D47,F47*G47,($D$19-C47)*G47)) -> 3749.95 | I47: =0.0001+(D46-C46)*G46+I46 -> 0.0001
B48: =+"From LCU "&C48&" to LCU "&D48 -> From LCU 410001 to LCU 10000000 | C48: 410001 | D48: 10000000 | E48: =D47 -> 410000 | F48: =IF($D$19<C48,0,IF($D$19>D48,D48-C48,$D$19-C48)) -> 9589999 | G48: 0.1 | H48: =IF($D$19<C48,0,IF($D$19>D48,F48*G48,($D$19-C48)*G48)) -> 958999.9 | I48: =0.0001+(D47-C47)*G47+I47 -> 3749.9502
B49: =+"From LCU "&C49&" to LCU "&D49 -> From LCU to LCU | E49: =D48 -> 10000000 | F49: =IF($D$19<C49,0,IF($D$19>D49,D49-C49,$D$19-C49)) -> 0 | G49: 0.15 | H49: =IF($D$19<C49,0,IF($D$19>D49,F49*G49,($D$19-C49)*G49)) -> 0 | I49: =0.0001+(D48-C48)*G48+I48 -> 962749.85
B50: =+"From LCU "&C50&" to LCU "&D50 -> From LCU to LCU | E50: =D49 -> 0 | F50: =IF($D$19<C50,0,IF($D$19>D50,D50-C50,$D$19-C50)) -> 0 | G50: 0.2 | H50: =IF($D$19<C50,0,IF($D$19>D50,F50*G50,($D$19-C50)*G50)) -> 0 | I50: =0.0001+(D49-C49)*G49+I49 -> 962749.85
B51: =+"From LCU "&C51&" to LCU "&D51 -> From LCU to LCU | E51: =D50 -> 0 | F51: =IF($D$19<C51,0,IF($D$19>D51,D51-C51,$D$19-C51)) -> 0 | G51: 0.25 | H51: =IF($D$19<C51,0,IF($D$19>D51,F51*G51,($D$19-C51)*G51)) -> 0 | I51: =0.0001+(D50-C50)*G50+I50 -> 962749.85
B52: =+"From LCU "&C52&" to LCU "&D52 -> From LCU to LCU | E52: =D51 -> 0 | F52: =IF($D$19<C52,0,IF($D$19>D52,D52-C52,$D$19-C52)) -> 0 | G52: 0.3 | H52: =IF($D$19<C52,0,IF($D$19>D52,F52*G52,($D$19-C52)*G52)) -> 0 | I52: =0.0001+(D51-C51)*G51+I51 -> 962749.85
B53: =+"From LCU "&C53&" to LCU "&D53 -> From LCU to LCU | E53: =D52 -> 0 | G53: 0.35 | H53: =IF($D$19<C53,0,IF($D$19>D53,F53*G53,($D$19-C53)*G53)) -> 0

Sheet Background calculations
B2: Background calculations & assumptions
B4: Guidance
B5: This tab contains all the background calculations & assumptions to calculate the LI benchmark. Do not edit any of the cells in this tab
B7: 0. MODEL SETTINGS
B9: LIST - Referense Size | C9: Household size - Selected | D9: ='OUTPUT_Living wage'!E15 -> Personalized | F9: Household composition - selected | G9: =D9 -> Personalized
B10: Reference Household | C10: ='OUTPUT_Living wage'!C18 -> Number of adults | D10: ='OUTPUT_Living wage'!E18 -> 2 | F10: Adults (male) | G10: =IF('OUTPUT_Living wage'!$E$15='Background calculations'!$B$11,'1. Setting the boundaries'!D25,1) -> 1
B11: Personalized | C11: ='OUTPUT_Living wage'!C19 -> Number of children | D11: ='OUTPUT_Living wage'!E19 -> 2 | F11: Adults (female) | G11: =IF('OUTPUT_Living wage'!$E$15='Background calculations'!$B$11,'1. Setting the boundaries'!D26,1) -> 1
C12: ='OUTPUT_Living wage'!C20 -> Number of working adults | D12: ='OUTPUT_Living wage'!E20 -> 2 | F12: Children | G12: =IF('OUTPUT_Living wage'!$E$15='Background calculations'!$B$11,'1. Setting the boundaries'!D27,D11) -> 2
B16: I. HOUSEHOLD SETUP
B19: 2A) Calculate number of children
B21: Corrected fertility rate | C21: ='1. Setting the boundaries'!D45*(1-('1. Setting the boundaries'!D46/1000)) -> 0.1623125 | D21: ='1. Setting the boundaries'!E45*(1-('1. Setting the boundaries'!E46/1000)) -> 0.1623125 | E21: ='1. Setting the boundaries'!F45*(1-('1. Setting the boundaries'!F46/1000)) -> 0.162975
B23: Household size (final calculation) | C23: =AVERAGE('1. Setting the boundaries'!D44,'1. Setting the boundaries'!F44) -> 0.12916667 | D23: =AVERAGE('1. Setting the boundaries'!E44,'1. Setting the boundaries'!F44) -> 0.12916667 | E23: ='1. Setting the boundaries'!F44 -> 0.12916667
B24: Number of children (method 1) | C24: =C23-'1. Setting the boundaries'!$D$16 -> -1.8708333 | D24: =D23-'1. Setting the boundaries'!$D$16 -> -1.8708333 | E24: =IF(E23-'1. Setting the boundaries'!$D$16<0,0,E23-'1. Setting the boundaries'!$D$16) -> 0
B25: Number of children (method 2) | C25: =C21 -> 0.1623125 | D25: =D21 -> 0.1623125 | E25: =E21 -> 0.162975
B27: 2B) Calculate number of workers in the family
B29: Probability of full time equivalent work per person | C29: ='1. Setting the boundaries'!D64*(100%-'1. Setting the boundaries'!D65)*(100%-('1. Setting the boundaries'!D66/2)) -> 0.692677 | D29: ='1. Setting the boundaries'!E64*(100%-'1. Setting the boundaries'!E65)*(100%-('1. Setting the boundaries'!E66/2)) -> 0.775515 | E29: ='1. Setting the boundaries'!F64*(100%-'1. Setting the boundaries'!F65)*(100%-('1. Setting the boundaries'!F66/2)) -> 0.733902
B30: Probability of full time equivalent work per person (number) | C30: =C29 -> 0.692677 | D30: =D29 -> 0.775515 | E30: =E29 -> 0.733902
B33: II. HOUSING COST CALCULATIONS
B35: Space per person required if minimum number of rooms is not met
B37: Minimum space per person (sqm) | C37: 6
B39: Decent Housing Standard Analysis
I41: MANDATORY CRITERIA | N41: ADDITIONAL CRITERIA
B42: Participant | C42: Decent Housing Standard | D42: Household size | E42: FTE | F42: Total Rooms | G42: Persons per room | H42: living space (sq mt) | I42: Living space per person | J42: Floor | K42: Roof | L42: Walls | M42: Mandatory criteria met? | N42: Safe Toilet | O42: Access to water | P42: Adequate ventilation when cooking inside | Q42: Availability of electricity | R42: Additional criteria met? (3 out of 4) | S42: Include in study
B43: Survey #1 | C43: =AND('Background calculations'!M43,'Background calculations'!R43,S43="Yes") -> TRUE | D43: {=TRANSPOSE('CLS - Input data'!D18:R18)} -> 4 | E43: {=TRANSPOSE('CLS - Input data'!D20:R20)+TRANSPOSE('CLS - Input data'!D21:R21)} -> 2 | F43: {=TRANSPOSE('CLS - Input data'!D23:R23)} -> 3 | G43: {=TRANSPOSE('Background calculations'!C65:Q65)} -> 1.3333333 | H43: {=TRANSPOSE('CLS - Input data'!D24:R24)} -> 25.08 | I43: =H43/D43 -> 6.27 | J43: {=TRANSPOSE('Decent housing'!E30:S30)} -> Yes | K43: {=TRANSPOSE('Decent housing'!E29:S29)} -> Yes | L43: {=TRANSPOSE('Decent housing'!E28:S28)} -> Yes | M43: =AND(IF(G43<='2. Housing costs'!$D$28,TRUE,H43/D43 >='Background calculations'!$C$37),J43="Yes",K43="Yes",L43="Yes") -> TRUE | N43: {=TRANSPOSE('Decent housing'!E31:S31)} -> Yes | O43: {=TRANSPOSE('Decent housing'!E32:S32)} -> Yes | P43: {=TRANSPOSE('Decent housing'!E33:S33)} -> Yes | Q43: {=TRANSPOSE('Decent housing'!E34:S34)} -> Yes | R43: =COUNTIF(N43:Q43,"Yes")>=3 -> TRUE | S43: {=TRANSPOSE('Decent housing'!E27:S27)} -> Yes
B44: Survey #2 | C44: =AND('Background calculations'!M44,'Background calculations'!R44,S44="Yes") -> TRUE | D44: 4 | E44: 2 | F44: 2 | G44: 2 | H44: 40.25 | I44: =H44/D44 -> 10.0625 | J44: Yes | K44: Yes | L44: Yes | M44: =AND(IF(G44<='2. Housing costs'!$D$28,TRUE,H44/D44 >='Background calculations'!$C$37),J44="Yes",K44="Yes",L44="Yes") -> TRUE | N44: Yes | O44: Yes | P44: Yes | Q44: Yes | R44: =COUNTIF(N44:Q44,"Yes")>=3 -> TRUE | S44: Yes
